<?xml version="1.0" ?>
<robot name="hermes">
  <link name="base_link">
    <inertial>
      <mass value="1.0" />
      <inertia ixx="0.015" iyy="0.0375" izz="0.0375" ixy="0" ixz="0" iyz="0" />
    </inertial>
    <visual>
      <geometry>
        <box size="1.16195 0.651 0.77596" />
      </geometry>
      <material name="silver">
        <color rgba="0.75 0.75 0.75 1" />
      </material>
    </visual>
    <collision>
      <geometry>
        <box size="0.6 0.3 0.3" />
      </geometry>
    </collision>
  </link>
  <link name="back_caster">
    <inertial>
      <mass value="0.1" />
      <inertia ixx="0.00083" iyy="0.00083" izz="0.000167" ixy="0" ixz="0" iyz="0" />
    </inertial>
    <visual>
      <geometry>
        <box size="0.1 0.1 0.77596" />
      </geometry>
      <material name="silver" />
    </visual>
    <collision>
      <geometry>
        <box size="0.1 0.1 0.77596" />
      </geometry>
    </collision>
  </link>
  <joint name="back_caster_joint" type="continuous">
    <axis xyz="0 0 1" />
    <parent link="base_link" />
    <child link="back_caster" />
    <origin rpy="0 0 0" xyz="-0.491695 0 0" />
  </joint>
  <link name="back_wheel">
    <inertial>
      <mass value="0.1" />
      <inertia ixx="5.1458e-5" iyy="5.1458e-5" izz="6.125e-5" ixy="0" ixz="0" iyz="0" />
    </inertial>
    <visual>
      <geometry>
        <cylinder length="0.05" radius="0.1" />
      </geometry>
      <material name="black" />
    </visual>
    <collision>
      <geometry>
        <cylinder length="0.05" radius="0.1" />
      </geometry>
    </collision>

  </link>
  <joint name="back_wheel_joint" type="continuous">
    <axis xyz="0 0 1" />
    <parent link="back_caster" />
    <child link="back_wheel" />
    <origin rpy="-1.5708 0 0" xyz="0.05 0 -.38798" />
  </joint>
  <link name="front_caster">
    <inertial>
      <mass value="0.1" />
      <inertia ixx="0.00083" iyy="0.00083" izz="0.000167" ixy="0" ixz="0" iyz="0" />
    </inertial>
    <visual>
      <geometry>
        <box size="0.1 0.1 0.77596" />
      </geometry>
      <material name="silver" />
    </visual>
    <collision>
      <geometry>
        <box size="0.1 0.1 0.77596" />
      </geometry>
    </collision>
  </link>
  <joint name="front_caster_joint" type="continuous">
    <axis xyz="0 0 1" />
    <parent link="base_link" />
    <child link="front_caster" />
    <origin rpy="0 0 0" xyz="0.491695 0 0" />
  </joint>
  <link name="front_wheel">
    <inertial>
      <mass value="0.1" />
      <inertia ixx="5.1458e-5" iyy="5.1458e-5" izz="6.125e-5" ixy="0" ixz="0" iyz="0" />
    </inertial>
    <visual>
      <geometry>
        <cylinder length="0.05" radius="0.1" />
      </geometry>
      <material name="black" />
    </visual>
    <collision>
      <geometry>
        <cylinder length="0.05" radius="0.1" />
      </geometry>
    </collision>

  </link>
  <joint name="front_wheel_joint" type="continuous">
    <axis xyz="0 0 1" />
    <parent link="front_caster" />
    <child link="front_wheel" />
    <origin rpy="-1.5708 0 0" xyz="0.05 0 -.38798" />
  </joint>
  <link name="right_wheel">
    <inertial>
      <mass value="0.1" />
      <inertia ixx="5.1458e-5" iyy="5.1458e-5" izz="6.125e-5" ixy="0" ixz="0" iyz="0" />
    </inertial>
    <visual>
      <geometry>
        <cylinder length="0.05" radius="0.1" />
      </geometry>
      <material name="black">
        <color rgba="0 0 0 1" />
      </material>
    </visual>
    <collision>
      <geometry>
        <cylinder length="0.05" radius="0.1" />
      </geometry>
    </collision>
  </link>
  <joint name="right_wheel_joint" type="continuous">
    <axis xyz="0 0 1" />
    <parent link="base_link" />
    <child link="right_wheel" />
    <origin rpy="-1.5708 0 0" xyz="0.159795 -.3005 -.38798" />
  </joint>
  <link name="left_wheel">
    <inertial>
      <mass value="0.1" />
      <inertia ixx="5.1458e-5" iyy="5.1458e-5" izz="6.125e-5" ixy="0" ixz="0" iyz="0" />
    </inertial>
    <visual>
      <geometry>
        <cylinder length="0.05" radius="0.1" />
      </geometry>
      <material name="black" />
    </visual>
    <collision>
      <geometry>
        <cylinder length="0.05" radius="0.1" />
      </geometry>
    </collision>
  </link>
  <joint name="left_wheel_joint" type="continuous">
    <axis xyz="0 0 1" />
    <parent link="base_link" />
    <child link="left_wheel" />
    <origin rpy="-1.5708 0 0" xyz="0.159795 0.3005 -.38978" />
  </joint>
  <link name="lidar_link">
    <collision>
      <origin xyz="0 0 0" rpy="0 0 0" />
      <geometry>
        <box size="0.1 0.1 0.1" />
      </geometry>
    </collision>
    <visual>
      <origin xyz="0 0 0" rpy="0 0 0" />
      <geometry>
        <box size="0.1 0.1 0.1" />
      </geometry>
    </visual>
    <inertial>
      <mass value="1e-5" />
      <origin xyz="0 0 0" rpy="0 0 0" />
      <inertia ixx="1e-6" ixy="0" ixz="0" iyy="1e-6" iyz="0" izz="1e-6" />
    </inertial>
  </link>
  <joint name="lidar_joint" type="fixed">
    <origin xyz="0.630975 0 -0.1807467" rpy="0 0 0" />
    <parent link="base_link" />
    <child link="lidar_link" />
  </joint>
  <link name="camera_link">
    <visual>
      <origin rpy="0 0 0" xyz="0 0 0" />
      <geometry>
        <box size="0.05 0.05 0.05" />
      </geometry>
      <material name="Blue" />
    </visual>
  </link>
  <joint name="camera_joint" type="fixed">
    <origin rpy="0 1.0466 0" xyz="0.555975 0 0.72404" />
    <parent link="base_link" />
    <child link="camera_link" />
  </joint>
  <link name="imu_link">
    <visual>
      <origin rpy="0 0 0" xyz="0 0 0" />
      <geometry>
        <box size="0.05 0.05 0.05" />
      </geometry>
      <material name="Blue" />
    </visual>
  </link>
  <joint name="imu_joint" type="fixed">
    <origin rpy="0 0 0" xyz="0.16 0 0" />
    <parent link="base_link" />
    <child link="imu_link" />
  </joint>
  <link name="gps_link">
    <visual>
      <origin rpy="0 0 0" xyz="0 0 0" />
      <geometry>
        <box size="0.1 0.1 0.1" />
      </geometry>
      <material name="Blue" />
    </visual>
  </link>
  <joint name="gps_joint" type="fixed">
    <origin rpy="0 0 0" xyz="0.16 0 0.48011" />
    <parent link="base_link" />
    <child link="gps_link" />
  </joint>
  <gazebo>
    <plugin name="differential_drive_controller" filename="libgazebo_ros_diff_drive.so">
      <leftJoint>left_wheel_joint</leftJoint>
      <odometryTopic>odom</odometryTopic>
      <odometryFrame>odom</odometryFrame>
      <publishWheelTF>false</publishWheelTF>
      <publishOdomTF>true</publishOdomTF>
      <wheelTorque>5</wheelTorque>
      <wheelAcceleration>0</wheelAcceleration>
      <updateRate>100</updateRate>
      <odometrySource>world</odometrySource> <!-- 'encoder' instead of 'world' is also possible -->
      <publishTf>1</publishTf>
      <rosDebugLevel>na</rosDebugLevel>
      <rightJoint>right_wheel_joint</rightJoint>
      <robotBaseFrame>base_link</robotBaseFrame>
      <wheelSeparation>0.25</wheelSeparation>
      <wheelDiameter>0.07</wheelDiameter>
      <publishWheelJointState>true</publishWheelJointState>
      <commandTopic>cmd_vel</commandTopic>
      <robotBaseFrame>base_link</robotBaseFrame>
    </plugin>
  </gazebo>
  <gazebo reference="lidar_link">
    <sensor name="head_lidar_sensor" type="ray">
      <pose>0 0 0 0 0 0</pose>
      <visualize>true</visualize>
      <update_rate>25</update_rate> <!-- choosen for SICK LMS111-->
      <ray>
        <scan>
          <horizontal>
            <samples>720</samples>
            <resolution>1</resolution>
            <min_angle>-2.35619</min_angle>
            <max_angle>2.35619</max_angle>
          </horizontal>
        </scan>
        <range>
          <min>0.5</min>
          <max>20.0</max>
          <resolution>0.001</resolution>
        </range>
      </ray>
      <plugin filename="libgazebo_ros_laser.so" name="gazebo_ros_head_hokuyo_controller">
        <topicName>/scan</topicName>
        <frameName>lidar_link</frameName>
      </plugin>
    </sensor>
  </gazebo>
  <gazebo reference="camera_link">
    <sensor type="camera" name="camera1">
      <update_rate>30.0</update_rate>
      <camera name="head">
        <horizontal_fov>1.396</horizontal_fov>
        <image>
          <width>800</width>
          <height>800</height>
          <format>R8G8B8</format>
        </image>
        <clip>
          <near>0.02</near>
          <far>300</far>
        </clip>
        <noise>
          <type>gaussian</type>
          <mean>0.0</mean>
          <stddev>0.007</stddev>
        </noise>
      </camera>
      <plugin name="camera_controller" filename="libgazebo_ros_camera.so">
        <alwaysOn>true</alwaysOn>
        <updateRate>0.0</updateRate>
        <cameraName>mando/camera</cameraName>
        <imageTopicName>image_raw</imageTopicName>
        <cameraInfoTopicName>camera_info</cameraInfoTopicName>
        <frameName>camera_link</frameName>
        <hackBaseline>0.07</hackBaseline>
        <distortionK1>0.0</distortionK1>
        <distortionK2>0.0</distortionK2>
        <distortionK3>0.0</distortionK3>
        <distortionT1>0.0</distortionT1>
        <distortionT2>0.0</distortionT2>
      </plugin>
    </sensor>
  </gazebo>
  <!-- gps-->
  <gazebo>
    <plugin name="novatel_gps_sim" filename="libhector_gazebo_ros_gps.so">
      <alwaysOn>1</alwaysOn>
      <updateRate>10.0</updateRate>
      <bodyName>gps_link</bodyName>
      <topicName>gps</topicName>
      <velocityTopicName>gps_velocity</velocityTopicName>
      <drift>5.0 5.0 5.0</drift>
      <gaussianNoise>0.1 0.1 0.1</gaussianNoise>
      <velocityDrift>0 0 0</velocityDrift>
      <velocityGaussianNoise>0.1 0.1 0.1</velocityGaussianNoise>
    </plugin>
  </gazebo>
  <!-- imu -->
  <gazebo reference="imu_link">
    <gravity>true</gravity>
    <sensor name="imu_sensor" type="imu">
      <always_on>true</always_on>
      <update_rate>100.0</update_rate>
      <visualize>false</visualize>
      <topic>imu</topic>
      <plugin filename="libgazebo_ros_imu_sensor.so" name="imu_plugin">
        <topicName>imu</topicName>
        <bodyName>imu_link</bodyName>
        <updateRateHZ>100.0</updateRateHZ>
        <gaussianNoise>0.0</gaussianNoise>
        <xyzOffset>0 0 0</xyzOffset>
        <rpyOffset>0 0 0</rpyOffset>
        <frameName>imu_link</frameName>
      </plugin>
      <pose>0 0 0 0 0 0</pose>
    </sensor>
  </gazebo>
</robot>